[2023-09-19T07:06:26.030+0000] {taskinstance.py:1157} INFO - Dependencies all met for dep_context=non-requeueable deps ti=<TaskInstance: weather_data.extract_data manual__2023-09-19T07:06:25.251248+00:00 [queued]>
[2023-09-19T07:06:26.034+0000] {taskinstance.py:1157} INFO - Dependencies all met for dep_context=requeueable deps ti=<TaskInstance: weather_data.extract_data manual__2023-09-19T07:06:25.251248+00:00 [queued]>
[2023-09-19T07:06:26.034+0000] {taskinstance.py:1359} INFO - Starting attempt 1 of 1
[2023-09-19T07:06:26.041+0000] {taskinstance.py:1380} INFO - Executing <Task(PythonVirtualenvOperator): extract_data> on 2023-09-19 07:06:25.251248+00:00
[2023-09-19T07:06:26.045+0000] {standard_task_runner.py:57} INFO - Started process 4501 to run task
[2023-09-19T07:06:26.048+0000] {standard_task_runner.py:84} INFO - Running: ['***', 'tasks', 'run', 'weather_data', 'extract_data', 'manual__2023-09-19T07:06:25.251248+00:00', '--job-id', '55', '--raw', '--subdir', 'DAGS_FOLDER/weather_dag.py', '--cfg-path', '/tmp/tmpr2fzlu3l']
[2023-09-19T07:06:26.049+0000] {standard_task_runner.py:85} INFO - Job 55: Subtask extract_data
[2023-09-19T07:06:26.075+0000] {task_command.py:415} INFO - Running <TaskInstance: weather_data.extract_data manual__2023-09-19T07:06:25.251248+00:00 [running]> on host 973481dcacb6
[2023-09-19T07:06:26.118+0000] {taskinstance.py:1660} INFO - Exporting env vars: AIRFLOW_CTX_DAG_OWNER='***' AIRFLOW_CTX_DAG_ID='weather_data' AIRFLOW_CTX_TASK_ID='extract_data' AIRFLOW_CTX_EXECUTION_DATE='2023-09-19T07:06:25.251248+00:00' AIRFLOW_CTX_TRY_NUMBER='1' AIRFLOW_CTX_DAG_RUN_ID='manual__2023-09-19T07:06:25.251248+00:00'
[2023-09-19T07:06:26.120+0000] {process_utils.py:182} INFO - Executing cmd: /usr/local/bin/python -m virtualenv /tmp/venvr7gz5bii --system-site-packages
[2023-09-19T07:06:26.126+0000] {process_utils.py:186} INFO - Output:
[2023-09-19T07:06:26.713+0000] {process_utils.py:190} INFO - created virtual environment CPython3.8.18.final.0-64 in 146ms
[2023-09-19T07:06:26.714+0000] {process_utils.py:190} INFO -   creator CPython3Posix(dest=/tmp/venvr7gz5bii, clear=False, no_vcs_ignore=False, global=True)
[2023-09-19T07:06:26.714+0000] {process_utils.py:190} INFO -   seeder FromAppData(download=False, pip=bundle, setuptools=bundle, wheel=bundle, via=copy, app_data_dir=/home/***/.local/share/virtualenv)
[2023-09-19T07:06:26.715+0000] {process_utils.py:190} INFO -     added seed packages: pip==23.2, setuptools==68.0.0, wheel==0.40.0
[2023-09-19T07:06:26.715+0000] {process_utils.py:190} INFO -   activators BashActivator,CShellActivator,FishActivator,NushellActivator,PowerShellActivator,PythonActivator
[2023-09-19T07:06:26.736+0000] {process_utils.py:182} INFO - Executing cmd: /tmp/venvr7gz5bii/bin/pip install -r /tmp/venvr7gz5bii/requirements.txt
[2023-09-19T07:06:26.743+0000] {process_utils.py:186} INFO - Output:
[2023-09-19T07:06:27.862+0000] {process_utils.py:190} INFO - Collecting *** (from -r /tmp/venvr7gz5bii/requirements.txt (line 1))
[2023-09-19T07:06:27.864+0000] {process_utils.py:190} INFO -   Using cached ***-0.6.tar.gz (1.2 kB)
[2023-09-19T07:06:27.866+0000] {process_utils.py:190} INFO -   Preparing metadata (setup.py): started
[2023-09-19T07:06:28.277+0000] {process_utils.py:190} INFO -   Preparing metadata (setup.py): finished with status 'error'
[2023-09-19T07:06:28.281+0000] {process_utils.py:190} INFO -   error: subprocess-exited-with-error
[2023-09-19T07:06:28.282+0000] {process_utils.py:190} INFO - 
[2023-09-19T07:06:28.282+0000] {process_utils.py:190} INFO -   × python setup.py egg_info did not run successfully.
[2023-09-19T07:06:28.282+0000] {process_utils.py:190} INFO -   │ exit code: 1
[2023-09-19T07:06:28.282+0000] {process_utils.py:190} INFO -   ╰─> [14 lines of output]
[2023-09-19T07:06:28.282+0000] {process_utils.py:190} INFO -       running egg_info
[2023-09-19T07:06:28.283+0000] {process_utils.py:190} INFO -       creating /tmp/pip-pip-egg-info-roz4pxrt/***.egg-info
[2023-09-19T07:06:28.283+0000] {process_utils.py:190} INFO -       writing /tmp/pip-pip-egg-info-roz4pxrt/***.egg-info/PKG-INFO
[2023-09-19T07:06:28.283+0000] {process_utils.py:190} INFO -       writing dependency_links to /tmp/pip-pip-egg-info-roz4pxrt/***.egg-info/dependency_links.txt
[2023-09-19T07:06:28.284+0000] {process_utils.py:190} INFO -       writing top-level names to /tmp/pip-pip-egg-info-roz4pxrt/***.egg-info/top_level.txt
[2023-09-19T07:06:28.284+0000] {process_utils.py:190} INFO -       writing manifest file '/tmp/pip-pip-egg-info-roz4pxrt/***.egg-info/SOURCES.txt'
[2023-09-19T07:06:28.284+0000] {process_utils.py:190} INFO -       reading manifest file '/tmp/pip-pip-egg-info-roz4pxrt/***.egg-info/SOURCES.txt'
[2023-09-19T07:06:28.284+0000] {process_utils.py:190} INFO -       writing manifest file '/tmp/pip-pip-egg-info-roz4pxrt/***.egg-info/SOURCES.txt'
[2023-09-19T07:06:28.285+0000] {process_utils.py:190} INFO -       Traceback (most recent call last):
[2023-09-19T07:06:28.285+0000] {process_utils.py:190} INFO -         File "<string>", line 2, in <module>
[2023-09-19T07:06:28.285+0000] {process_utils.py:190} INFO -         File "<pip-setuptools-caller>", line 34, in <module>
[2023-09-19T07:06:28.286+0000] {process_utils.py:190} INFO -         File "/tmp/pip-install-hadp6knd/***_2979b882242d463595f986d385e4d65f/setup.py", line 32, in <module>
[2023-09-19T07:06:28.286+0000] {process_utils.py:190} INFO -           raise RuntimeError('Please install package apache-*** instead of ***')
[2023-09-19T07:06:28.286+0000] {process_utils.py:190} INFO -       RuntimeError: Please install package apache-*** instead of ***
[2023-09-19T07:06:28.286+0000] {process_utils.py:190} INFO -       [end of output]
[2023-09-19T07:06:28.287+0000] {process_utils.py:190} INFO - 
[2023-09-19T07:06:28.287+0000] {process_utils.py:190} INFO -   note: This error originates from a subprocess, and is likely not a problem with pip.
[2023-09-19T07:06:28.287+0000] {process_utils.py:190} INFO - error: metadata-generation-failed
[2023-09-19T07:06:28.288+0000] {process_utils.py:190} INFO - 
[2023-09-19T07:06:28.288+0000] {process_utils.py:190} INFO - × Encountered error while generating package metadata.
[2023-09-19T07:06:28.288+0000] {process_utils.py:190} INFO - ╰─> See above for output.
[2023-09-19T07:06:28.288+0000] {process_utils.py:190} INFO - 
[2023-09-19T07:06:28.288+0000] {process_utils.py:190} INFO - note: This is an issue with the package mentioned above, not pip.
[2023-09-19T07:06:28.289+0000] {process_utils.py:190} INFO - hint: See above for details.
[2023-09-19T07:06:28.490+0000] {process_utils.py:190} INFO - 
[2023-09-19T07:06:28.490+0000] {process_utils.py:190} INFO - [notice] A new release of pip is available: 23.2 -> 23.2.1
[2023-09-19T07:06:28.490+0000] {process_utils.py:190} INFO - [notice] To update, run: python -m pip install --upgrade pip
[2023-09-19T07:06:28.554+0000] {taskinstance.py:1935} ERROR - Task failed with exception
Traceback (most recent call last):
  File "/home/airflow/.local/lib/python3.8/site-packages/airflow/operators/python.py", line 395, in execute
    return super().execute(context=serializable_context)
  File "/home/airflow/.local/lib/python3.8/site-packages/airflow/operators/python.py", line 192, in execute
    return_value = self.execute_callable()
  File "/home/airflow/.local/lib/python3.8/site-packages/airflow/operators/python.py", line 594, in execute_callable
    prepare_virtualenv(
  File "/home/airflow/.local/lib/python3.8/site-packages/airflow/utils/python_virtualenv.py", line 100, in prepare_virtualenv
    execute_in_subprocess(pip_cmd)
  File "/home/airflow/.local/lib/python3.8/site-packages/airflow/utils/process_utils.py", line 171, in execute_in_subprocess
    execute_in_subprocess_with_kwargs(cmd, cwd=cwd)
  File "/home/airflow/.local/lib/python3.8/site-packages/airflow/utils/process_utils.py", line 194, in execute_in_subprocess_with_kwargs
    raise subprocess.CalledProcessError(exit_code, cmd)
subprocess.CalledProcessError: Command '['/tmp/venvr7gz5bii/bin/pip', 'install', '-r', '/tmp/venvr7gz5bii/requirements.txt']' returned non-zero exit status 1.
[2023-09-19T07:06:28.561+0000] {taskinstance.py:1398} INFO - Marking task as FAILED. dag_id=weather_data, task_id=extract_data, execution_date=20230919T070625, start_date=20230919T070626, end_date=20230919T070628
[2023-09-19T07:06:28.568+0000] {standard_task_runner.py:104} ERROR - Failed to execute job 55 for task extract_data (Command '['/tmp/venvr7gz5bii/bin/pip', 'install', '-r', '/tmp/venvr7gz5bii/requirements.txt']' returned non-zero exit status 1.; 4501)
[2023-09-19T07:06:28.602+0000] {local_task_job_runner.py:228} INFO - Task exited with return code 1
[2023-09-19T07:06:28.615+0000] {taskinstance.py:2776} INFO - 0 downstream tasks scheduled from follow-on schedule check
