[2023-09-19T07:23:44.882+0000] {taskinstance.py:1157} INFO - Dependencies all met for dep_context=non-requeueable deps ti=<TaskInstance: weather_data.extract_data manual__2023-09-19T07:23:44.102111+00:00 [queued]>
[2023-09-19T07:23:44.886+0000] {taskinstance.py:1157} INFO - Dependencies all met for dep_context=requeueable deps ti=<TaskInstance: weather_data.extract_data manual__2023-09-19T07:23:44.102111+00:00 [queued]>
[2023-09-19T07:23:44.886+0000] {taskinstance.py:1359} INFO - Starting attempt 1 of 1
[2023-09-19T07:23:44.892+0000] {taskinstance.py:1380} INFO - Executing <Task(PythonOperator): extract_data> on 2023-09-19 07:23:44.102111+00:00
[2023-09-19T07:23:44.896+0000] {standard_task_runner.py:57} INFO - Started process 4824 to run task
[2023-09-19T07:23:44.899+0000] {standard_task_runner.py:84} INFO - Running: ['***', 'tasks', 'run', 'weather_data', 'extract_data', 'manual__2023-09-19T07:23:44.102111+00:00', '--job-id', '58', '--raw', '--subdir', 'DAGS_FOLDER/weather_dag.py', '--cfg-path', '/tmp/tmpohsbq05b']
[2023-09-19T07:23:44.900+0000] {standard_task_runner.py:85} INFO - Job 58: Subtask extract_data
[2023-09-19T07:23:44.927+0000] {task_command.py:415} INFO - Running <TaskInstance: weather_data.extract_data manual__2023-09-19T07:23:44.102111+00:00 [running]> on host 973481dcacb6
[2023-09-19T07:23:44.970+0000] {taskinstance.py:1660} INFO - Exporting env vars: AIRFLOW_CTX_DAG_OWNER='***' AIRFLOW_CTX_DAG_ID='weather_data' AIRFLOW_CTX_TASK_ID='extract_data' AIRFLOW_CTX_EXECUTION_DATE='2023-09-19T07:23:44.102111+00:00' AIRFLOW_CTX_TRY_NUMBER='1' AIRFLOW_CTX_DAG_RUN_ID='manual__2023-09-19T07:23:44.102111+00:00'
[2023-09-19T07:23:45.313+0000] {taskinstance.py:1935} ERROR - Task failed with exception
Traceback (most recent call last):
  File "/home/airflow/.local/lib/python3.8/site-packages/airflow/operators/python.py", line 192, in execute
    return_value = self.execute_callable()
  File "/home/airflow/.local/lib/python3.8/site-packages/airflow/operators/python.py", line 209, in execute_callable
    return self.python_callable(*self.op_args, **self.op_kwargs)
  File "/opt/airflow/dags/weather_dag.py", line 41, in download_data
    save_data(data, extraction_timestamp)
  File "/opt/airflow/dags/weather_dag.py", line 58, in save_data
    with open("../files/weather.json", "a") as f:
FileNotFoundError: [Errno 2] No such file or directory: '../files/weather.json'
[2023-09-19T07:23:45.319+0000] {taskinstance.py:1398} INFO - Marking task as FAILED. dag_id=weather_data, task_id=extract_data, execution_date=20230919T072344, start_date=20230919T072344, end_date=20230919T072345
[2023-09-19T07:23:45.325+0000] {standard_task_runner.py:104} ERROR - Failed to execute job 58 for task extract_data ([Errno 2] No such file or directory: '../files/weather.json'; 4824)
[2023-09-19T07:23:45.357+0000] {local_task_job_runner.py:228} INFO - Task exited with return code 1
[2023-09-19T07:23:45.371+0000] {taskinstance.py:2776} INFO - 0 downstream tasks scheduled from follow-on schedule check
