[2023-09-19T07:50:20.927+0000] {taskinstance.py:1157} INFO - Dependencies all met for dep_context=non-requeueable deps ti=<TaskInstance: weather_data.extract_data manual__2023-09-19T07:50:19.892568+00:00 [queued]>
[2023-09-19T07:50:20.933+0000] {taskinstance.py:1157} INFO - Dependencies all met for dep_context=requeueable deps ti=<TaskInstance: weather_data.extract_data manual__2023-09-19T07:50:19.892568+00:00 [queued]>
[2023-09-19T07:50:20.933+0000] {taskinstance.py:1359} INFO - Starting attempt 1 of 1
[2023-09-19T07:50:20.941+0000] {taskinstance.py:1380} INFO - Executing <Task(PythonOperator): extract_data> on 2023-09-19 07:50:19.892568+00:00
[2023-09-19T07:50:20.946+0000] {standard_task_runner.py:57} INFO - Started process 5240 to run task
[2023-09-19T07:50:20.950+0000] {standard_task_runner.py:84} INFO - Running: ['***', 'tasks', 'run', 'weather_data', 'extract_data', 'manual__2023-09-19T07:50:19.892568+00:00', '--job-id', '61', '--raw', '--subdir', 'DAGS_FOLDER/weather_dag.py', '--cfg-path', '/tmp/tmp44387lwz']
[2023-09-19T07:50:20.952+0000] {standard_task_runner.py:85} INFO - Job 61: Subtask extract_data
[2023-09-19T07:50:20.998+0000] {task_command.py:415} INFO - Running <TaskInstance: weather_data.extract_data manual__2023-09-19T07:50:19.892568+00:00 [running]> on host 973481dcacb6
[2023-09-19T07:50:21.051+0000] {taskinstance.py:1660} INFO - Exporting env vars: AIRFLOW_CTX_DAG_OWNER='***' AIRFLOW_CTX_DAG_ID='weather_data' AIRFLOW_CTX_TASK_ID='extract_data' AIRFLOW_CTX_EXECUTION_DATE='2023-09-19T07:50:19.892568+00:00' AIRFLOW_CTX_TRY_NUMBER='1' AIRFLOW_CTX_DAG_RUN_ID='manual__2023-09-19T07:50:19.892568+00:00'
[2023-09-19T07:50:21.392+0000] {taskinstance.py:1935} ERROR - Task failed with exception
Traceback (most recent call last):
  File "/home/airflow/.local/lib/python3.8/site-packages/airflow/operators/python.py", line 192, in execute
    return_value = self.execute_callable()
  File "/home/airflow/.local/lib/python3.8/site-packages/airflow/operators/python.py", line 209, in execute_callable
    return self.python_callable(*self.op_args, **self.op_kwargs)
  File "/opt/airflow/dags/weather_dag.py", line 39, in download_data
    save_data(data, extraction_timestamp)
  File "/opt/airflow/dags/weather_dag.py", line 56, in save_data
    with open("../files/weather.json", "a") as f:
FileNotFoundError: [Errno 2] No such file or directory: '../files/weather.json'
[2023-09-19T07:50:21.398+0000] {taskinstance.py:1398} INFO - Marking task as FAILED. dag_id=weather_data, task_id=extract_data, execution_date=20230919T075019, start_date=20230919T075020, end_date=20230919T075021
[2023-09-19T07:50:21.405+0000] {standard_task_runner.py:104} ERROR - Failed to execute job 61 for task extract_data ([Errno 2] No such file or directory: '../files/weather.json'; 5240)
[2023-09-19T07:50:21.452+0000] {local_task_job_runner.py:228} INFO - Task exited with return code 1
[2023-09-19T07:50:21.467+0000] {taskinstance.py:2776} INFO - 0 downstream tasks scheduled from follow-on schedule check
