[2023-09-20T06:28:23.367+0000] {taskinstance.py:1157} INFO - Dependencies all met for dep_context=non-requeueable deps ti=<TaskInstance: weather_data.extract_data scheduled__2023-09-19T00:00:00+00:00 [queued]>
[2023-09-20T06:28:23.370+0000] {taskinstance.py:1157} INFO - Dependencies all met for dep_context=requeueable deps ti=<TaskInstance: weather_data.extract_data scheduled__2023-09-19T00:00:00+00:00 [queued]>
[2023-09-20T06:28:23.371+0000] {taskinstance.py:1359} INFO - Starting attempt 1 of 1
[2023-09-20T06:28:23.376+0000] {taskinstance.py:1380} INFO - Executing <Task(PythonVirtualenvOperator): extract_data> on 2023-09-19 00:00:00+00:00
[2023-09-20T06:28:23.382+0000] {standard_task_runner.py:57} INFO - Started process 2428 to run task
[2023-09-20T06:28:23.386+0000] {standard_task_runner.py:84} INFO - Running: ['***', 'tasks', 'run', 'weather_data', 'extract_data', 'scheduled__2023-09-19T00:00:00+00:00', '--job-id', '82', '--raw', '--subdir', 'DAGS_FOLDER/weather_dag.py', '--cfg-path', '/tmp/tmpvmx1vv_c']
[2023-09-20T06:28:23.388+0000] {standard_task_runner.py:85} INFO - Job 82: Subtask extract_data
[2023-09-20T06:28:23.437+0000] {task_command.py:415} INFO - Running <TaskInstance: weather_data.extract_data scheduled__2023-09-19T00:00:00+00:00 [running]> on host 90bb52186339
[2023-09-20T06:28:23.492+0000] {taskinstance.py:1660} INFO - Exporting env vars: AIRFLOW_CTX_DAG_OWNER='***' AIRFLOW_CTX_DAG_ID='weather_data' AIRFLOW_CTX_TASK_ID='extract_data' AIRFLOW_CTX_EXECUTION_DATE='2023-09-19T00:00:00+00:00' AIRFLOW_CTX_TRY_NUMBER='1' AIRFLOW_CTX_DAG_RUN_ID='scheduled__2023-09-19T00:00:00+00:00'
[2023-09-20T06:28:23.495+0000] {process_utils.py:182} INFO - Executing cmd: /usr/local/bin/python -m virtualenv /tmp/venvs3jjng7c --system-site-packages
[2023-09-20T06:28:23.502+0000] {process_utils.py:186} INFO - Output:
[2023-09-20T06:28:24.308+0000] {process_utils.py:190} INFO - created virtual environment CPython3.8.18.final.0-64 in 379ms
[2023-09-20T06:28:24.309+0000] {process_utils.py:190} INFO -   creator CPython3Posix(dest=/tmp/venvs3jjng7c, clear=False, no_vcs_ignore=False, global=True)
[2023-09-20T06:28:24.309+0000] {process_utils.py:190} INFO -   seeder FromAppData(download=False, pip=bundle, setuptools=bundle, wheel=bundle, via=copy, app_data_dir=/home/***/.local/share/virtualenv)
[2023-09-20T06:28:24.310+0000] {process_utils.py:190} INFO -     added seed packages: pip==23.2, setuptools==68.0.0, wheel==0.40.0
[2023-09-20T06:28:24.310+0000] {process_utils.py:190} INFO -   activators BashActivator,CShellActivator,FishActivator,NushellActivator,PowerShellActivator,PythonActivator
[2023-09-20T06:28:24.348+0000] {process_utils.py:182} INFO - Executing cmd: /tmp/venvs3jjng7c/bin/pip install -r /tmp/venvs3jjng7c/requirements.txt
[2023-09-20T06:28:24.355+0000] {process_utils.py:186} INFO - Output:
[2023-09-20T06:28:27.715+0000] {process_utils.py:190} INFO - 
[2023-09-20T06:28:27.715+0000] {process_utils.py:190} INFO - [notice] A new release of pip is available: 23.2 -> 23.2.1
[2023-09-20T06:28:27.715+0000] {process_utils.py:190} INFO - [notice] To update, run: python -m pip install --upgrade pip
[2023-09-20T06:28:27.800+0000] {process_utils.py:182} INFO - Executing cmd: /tmp/venvs3jjng7c/bin/python /tmp/venvs3jjng7c/script.py /tmp/venvs3jjng7c/script.in /tmp/venvs3jjng7c/script.out /tmp/venvs3jjng7c/string_args.txt /tmp/venvs3jjng7c/termination.log
[2023-09-20T06:28:27.806+0000] {process_utils.py:186} INFO - Output:
[2023-09-20T06:28:28.452+0000] {process_utils.py:190} INFO - Traceback (most recent call last):
[2023-09-20T06:28:28.452+0000] {process_utils.py:190} INFO -   File "/tmp/venvs3jjng7c/script.py", line 46, in <module>
[2023-09-20T06:28:28.452+0000] {process_utils.py:190} INFO -     res = download_data(*arg_dict["args"], **arg_dict["kwargs"])
[2023-09-20T06:28:28.452+0000] {process_utils.py:190} INFO -   File "/tmp/venvs3jjng7c/script.py", line 28, in download_data
[2023-09-20T06:28:28.453+0000] {process_utils.py:190} INFO -     logging.basicConfig(
[2023-09-20T06:28:28.453+0000] {process_utils.py:190} INFO - NameError: name 'logging' is not defined
[2023-09-20T06:28:28.533+0000] {taskinstance.py:1935} ERROR - Task failed with exception
Traceback (most recent call last):
  File "/home/airflow/.local/lib/python3.8/site-packages/airflow/operators/python.py", line 395, in execute
    return super().execute(context=serializable_context)
  File "/home/airflow/.local/lib/python3.8/site-packages/airflow/operators/python.py", line 192, in execute
    return_value = self.execute_callable()
  File "/home/airflow/.local/lib/python3.8/site-packages/airflow/operators/python.py", line 602, in execute_callable
    result = self._execute_python_callable_in_subprocess(python_path, tmp_path)
  File "/home/airflow/.local/lib/python3.8/site-packages/airflow/operators/python.py", line 463, in _execute_python_callable_in_subprocess
    raise AirflowException(error_msg) from None
airflow.exceptions.AirflowException: Process returned non-zero exit status 1.
name 'logging' is not defined
[2023-09-20T06:28:28.536+0000] {taskinstance.py:1398} INFO - Marking task as FAILED. dag_id=weather_data, task_id=extract_data, execution_date=20230919T000000, start_date=20230920T062823, end_date=20230920T062828
[2023-09-20T06:28:28.543+0000] {standard_task_runner.py:104} ERROR - Failed to execute job 82 for task extract_data (Process returned non-zero exit status 1.
name 'logging' is not defined; 2428)
[2023-09-20T06:28:28.571+0000] {local_task_job_runner.py:228} INFO - Task exited with return code 1
[2023-09-20T06:28:28.582+0000] {taskinstance.py:2776} INFO - 0 downstream tasks scheduled from follow-on schedule check
