[2023-09-19T07:49:33.463+0000] {taskinstance.py:1157} INFO - Dependencies all met for dep_context=non-requeueable deps ti=<TaskInstance: weather_data.extract_data manual__2023-09-19T07:49:32.055740+00:00 [queued]>
[2023-09-19T07:49:33.467+0000] {taskinstance.py:1157} INFO - Dependencies all met for dep_context=requeueable deps ti=<TaskInstance: weather_data.extract_data manual__2023-09-19T07:49:32.055740+00:00 [queued]>
[2023-09-19T07:49:33.467+0000] {taskinstance.py:1359} INFO - Starting attempt 1 of 1
[2023-09-19T07:49:33.473+0000] {taskinstance.py:1380} INFO - Executing <Task(PythonOperator): extract_data> on 2023-09-19 07:49:32.055740+00:00
[2023-09-19T07:49:33.478+0000] {standard_task_runner.py:57} INFO - Started process 5221 to run task
[2023-09-19T07:49:33.481+0000] {standard_task_runner.py:84} INFO - Running: ['***', 'tasks', 'run', 'weather_data', 'extract_data', 'manual__2023-09-19T07:49:32.055740+00:00', '--job-id', '60', '--raw', '--subdir', 'DAGS_FOLDER/weather_dag.py', '--cfg-path', '/tmp/tmp36uliaqr']
[2023-09-19T07:49:33.482+0000] {standard_task_runner.py:85} INFO - Job 60: Subtask extract_data
[2023-09-19T07:49:33.510+0000] {task_command.py:415} INFO - Running <TaskInstance: weather_data.extract_data manual__2023-09-19T07:49:32.055740+00:00 [running]> on host 973481dcacb6
[2023-09-19T07:49:33.554+0000] {taskinstance.py:1660} INFO - Exporting env vars: AIRFLOW_CTX_DAG_OWNER='***' AIRFLOW_CTX_DAG_ID='weather_data' AIRFLOW_CTX_TASK_ID='extract_data' AIRFLOW_CTX_EXECUTION_DATE='2023-09-19T07:49:32.055740+00:00' AIRFLOW_CTX_TRY_NUMBER='1' AIRFLOW_CTX_DAG_RUN_ID='manual__2023-09-19T07:49:32.055740+00:00'
[2023-09-19T07:49:33.932+0000] {taskinstance.py:1935} ERROR - Task failed with exception
Traceback (most recent call last):
  File "/home/airflow/.local/lib/python3.8/site-packages/airflow/operators/python.py", line 192, in execute
    return_value = self.execute_callable()
  File "/home/airflow/.local/lib/python3.8/site-packages/airflow/operators/python.py", line 209, in execute_callable
    return self.python_callable(*self.op_args, **self.op_kwargs)
  File "/opt/airflow/dags/weather_dag.py", line 39, in download_data
    save_data(data, extraction_timestamp)
  File "/opt/airflow/dags/weather_dag.py", line 56, in save_data
    with open("../files/weather.json", "a") as f:
FileNotFoundError: [Errno 2] No such file or directory: '../files/weather.json'
[2023-09-19T07:49:33.953+0000] {taskinstance.py:1398} INFO - Marking task as FAILED. dag_id=weather_data, task_id=extract_data, execution_date=20230919T074932, start_date=20230919T074933, end_date=20230919T074933
[2023-09-19T07:49:33.966+0000] {standard_task_runner.py:104} ERROR - Failed to execute job 60 for task extract_data ([Errno 2] No such file or directory: '../files/weather.json'; 5221)
[2023-09-19T07:49:33.983+0000] {local_task_job_runner.py:228} INFO - Task exited with return code 1
[2023-09-19T07:49:34.004+0000] {taskinstance.py:2776} INFO - 0 downstream tasks scheduled from follow-on schedule check
