[2023-09-19T09:51:40.366+0000] {taskinstance.py:1157} INFO - Dependencies all met for dep_context=non-requeueable deps ti=<TaskInstance: weather_data.extract_data manual__2023-09-19T09:51:38.193287+00:00 [queued]>
[2023-09-19T09:51:40.370+0000] {taskinstance.py:1157} INFO - Dependencies all met for dep_context=requeueable deps ti=<TaskInstance: weather_data.extract_data manual__2023-09-19T09:51:38.193287+00:00 [queued]>
[2023-09-19T09:51:40.370+0000] {taskinstance.py:1359} INFO - Starting attempt 1 of 1
[2023-09-19T09:51:40.376+0000] {taskinstance.py:1380} INFO - Executing <Task(PythonOperator): extract_data> on 2023-09-19 09:51:38.193287+00:00
[2023-09-19T09:51:40.381+0000] {standard_task_runner.py:57} INFO - Started process 867 to run task
[2023-09-19T09:51:40.383+0000] {standard_task_runner.py:84} INFO - Running: ['***', 'tasks', 'run', 'weather_data', 'extract_data', 'manual__2023-09-19T09:51:38.193287+00:00', '--job-id', '71', '--raw', '--subdir', 'DAGS_FOLDER/weather_dag.py', '--cfg-path', '/tmp/tmpztk9ecbr']
[2023-09-19T09:51:40.384+0000] {standard_task_runner.py:85} INFO - Job 71: Subtask extract_data
[2023-09-19T09:51:40.412+0000] {task_command.py:415} INFO - Running <TaskInstance: weather_data.extract_data manual__2023-09-19T09:51:38.193287+00:00 [running]> on host 12ae14f8feaf
[2023-09-19T09:51:40.455+0000] {taskinstance.py:1660} INFO - Exporting env vars: AIRFLOW_CTX_DAG_OWNER='***' AIRFLOW_CTX_DAG_ID='weather_data' AIRFLOW_CTX_TASK_ID='extract_data' AIRFLOW_CTX_EXECUTION_DATE='2023-09-19T09:51:38.193287+00:00' AIRFLOW_CTX_TRY_NUMBER='1' AIRFLOW_CTX_DAG_RUN_ID='manual__2023-09-19T09:51:38.193287+00:00'
[2023-09-19T09:51:40.457+0000] {taskinstance.py:1935} ERROR - Task failed with exception
Traceback (most recent call last):
  File "/home/airflow/.local/lib/python3.8/site-packages/airflow/operators/python.py", line 192, in execute
    return_value = self.execute_callable()
  File "/home/airflow/.local/lib/python3.8/site-packages/airflow/operators/python.py", line 209, in execute_callable
    return self.python_callable(*self.op_args, **self.op_kwargs)
TypeError: download_data() missing 2 required positional arguments: 'places' and 'api_key'
[2023-09-19T09:51:40.463+0000] {taskinstance.py:1398} INFO - Marking task as FAILED. dag_id=weather_data, task_id=extract_data, execution_date=20230919T095138, start_date=20230919T095140, end_date=20230919T095140
[2023-09-19T09:51:40.469+0000] {standard_task_runner.py:104} ERROR - Failed to execute job 71 for task extract_data (download_data() missing 2 required positional arguments: 'places' and 'api_key'; 867)
[2023-09-19T09:51:40.476+0000] {local_task_job_runner.py:228} INFO - Task exited with return code 1
[2023-09-19T09:51:40.489+0000] {taskinstance.py:2776} INFO - 0 downstream tasks scheduled from follow-on schedule check
