[2023-09-19T07:16:00.740+0000] {taskinstance.py:1157} INFO - Dependencies all met for dep_context=non-requeueable deps ti=<TaskInstance: weather_data.extract_data manual__2023-09-19T07:15:59.835436+00:00 [queued]>
[2023-09-19T07:16:00.745+0000] {taskinstance.py:1157} INFO - Dependencies all met for dep_context=requeueable deps ti=<TaskInstance: weather_data.extract_data manual__2023-09-19T07:15:59.835436+00:00 [queued]>
[2023-09-19T07:16:00.745+0000] {taskinstance.py:1359} INFO - Starting attempt 1 of 1
[2023-09-19T07:16:00.753+0000] {taskinstance.py:1380} INFO - Executing <Task(PythonVirtualenvOperator): extract_data> on 2023-09-19 07:15:59.835436+00:00
[2023-09-19T07:16:00.759+0000] {standard_task_runner.py:57} INFO - Started process 4687 to run task
[2023-09-19T07:16:00.762+0000] {standard_task_runner.py:84} INFO - Running: ['***', 'tasks', 'run', 'weather_data', 'extract_data', 'manual__2023-09-19T07:15:59.835436+00:00', '--job-id', '57', '--raw', '--subdir', 'DAGS_FOLDER/weather_dag.py', '--cfg-path', '/tmp/tmpftb73n4k']
[2023-09-19T07:16:00.763+0000] {standard_task_runner.py:85} INFO - Job 57: Subtask extract_data
[2023-09-19T07:16:00.794+0000] {task_command.py:415} INFO - Running <TaskInstance: weather_data.extract_data manual__2023-09-19T07:15:59.835436+00:00 [running]> on host 973481dcacb6
[2023-09-19T07:16:00.839+0000] {taskinstance.py:1660} INFO - Exporting env vars: AIRFLOW_CTX_DAG_OWNER='***' AIRFLOW_CTX_DAG_ID='weather_data' AIRFLOW_CTX_TASK_ID='extract_data' AIRFLOW_CTX_EXECUTION_DATE='2023-09-19T07:15:59.835436+00:00' AIRFLOW_CTX_TRY_NUMBER='1' AIRFLOW_CTX_DAG_RUN_ID='manual__2023-09-19T07:15:59.835436+00:00'
[2023-09-19T07:16:00.842+0000] {process_utils.py:182} INFO - Executing cmd: /usr/local/bin/python -m virtualenv /tmp/venvxla5nf0v --system-site-packages
[2023-09-19T07:16:00.849+0000] {process_utils.py:186} INFO - Output:
[2023-09-19T07:16:01.463+0000] {process_utils.py:190} INFO - created virtual environment CPython3.8.18.final.0-64 in 158ms
[2023-09-19T07:16:01.463+0000] {process_utils.py:190} INFO -   creator CPython3Posix(dest=/tmp/venvxla5nf0v, clear=False, no_vcs_ignore=False, global=True)
[2023-09-19T07:16:01.463+0000] {process_utils.py:190} INFO -   seeder FromAppData(download=False, pip=bundle, setuptools=bundle, wheel=bundle, via=copy, app_data_dir=/home/***/.local/share/virtualenv)
[2023-09-19T07:16:01.464+0000] {process_utils.py:190} INFO -     added seed packages: pip==23.2, setuptools==68.0.0, wheel==0.40.0
[2023-09-19T07:16:01.464+0000] {process_utils.py:190} INFO -   activators BashActivator,CShellActivator,FishActivator,NushellActivator,PowerShellActivator,PythonActivator
[2023-09-19T07:16:01.485+0000] {process_utils.py:182} INFO - Executing cmd: /tmp/venvxla5nf0v/bin/pip install -r /tmp/venvxla5nf0v/requirements.txt
[2023-09-19T07:16:01.492+0000] {process_utils.py:186} INFO - Output:
[2023-09-19T07:16:02.805+0000] {process_utils.py:190} INFO - Collecting *** (from -r /tmp/venvxla5nf0v/requirements.txt (line 1))
[2023-09-19T07:16:02.808+0000] {process_utils.py:190} INFO -   Using cached ***-0.6.tar.gz (1.2 kB)
[2023-09-19T07:16:02.813+0000] {process_utils.py:190} INFO -   Preparing metadata (setup.py): started
[2023-09-19T07:16:03.244+0000] {process_utils.py:190} INFO -   Preparing metadata (setup.py): finished with status 'error'
[2023-09-19T07:16:03.248+0000] {process_utils.py:190} INFO -   error: subprocess-exited-with-error
[2023-09-19T07:16:03.248+0000] {process_utils.py:190} INFO - 
[2023-09-19T07:16:03.248+0000] {process_utils.py:190} INFO -   × python setup.py egg_info did not run successfully.
[2023-09-19T07:16:03.248+0000] {process_utils.py:190} INFO -   │ exit code: 1
[2023-09-19T07:16:03.249+0000] {process_utils.py:190} INFO -   ╰─> [14 lines of output]
[2023-09-19T07:16:03.249+0000] {process_utils.py:190} INFO -       running egg_info
[2023-09-19T07:16:03.249+0000] {process_utils.py:190} INFO -       creating /tmp/pip-pip-egg-info-5zmoqpmk/***.egg-info
[2023-09-19T07:16:03.249+0000] {process_utils.py:190} INFO -       writing /tmp/pip-pip-egg-info-5zmoqpmk/***.egg-info/PKG-INFO
[2023-09-19T07:16:03.250+0000] {process_utils.py:190} INFO -       writing dependency_links to /tmp/pip-pip-egg-info-5zmoqpmk/***.egg-info/dependency_links.txt
[2023-09-19T07:16:03.250+0000] {process_utils.py:190} INFO -       writing top-level names to /tmp/pip-pip-egg-info-5zmoqpmk/***.egg-info/top_level.txt
[2023-09-19T07:16:03.250+0000] {process_utils.py:190} INFO -       writing manifest file '/tmp/pip-pip-egg-info-5zmoqpmk/***.egg-info/SOURCES.txt'
[2023-09-19T07:16:03.250+0000] {process_utils.py:190} INFO -       reading manifest file '/tmp/pip-pip-egg-info-5zmoqpmk/***.egg-info/SOURCES.txt'
[2023-09-19T07:16:03.251+0000] {process_utils.py:190} INFO -       writing manifest file '/tmp/pip-pip-egg-info-5zmoqpmk/***.egg-info/SOURCES.txt'
[2023-09-19T07:16:03.251+0000] {process_utils.py:190} INFO -       Traceback (most recent call last):
[2023-09-19T07:16:03.251+0000] {process_utils.py:190} INFO -         File "<string>", line 2, in <module>
[2023-09-19T07:16:03.251+0000] {process_utils.py:190} INFO -         File "<pip-setuptools-caller>", line 34, in <module>
[2023-09-19T07:16:03.252+0000] {process_utils.py:190} INFO -         File "/tmp/pip-install-1k9j6d7f/***_0c64cb29580d46ec85533635aae4034f/setup.py", line 32, in <module>
[2023-09-19T07:16:03.252+0000] {process_utils.py:190} INFO -           raise RuntimeError('Please install package apache-*** instead of ***')
[2023-09-19T07:16:03.252+0000] {process_utils.py:190} INFO -       RuntimeError: Please install package apache-*** instead of ***
[2023-09-19T07:16:03.253+0000] {process_utils.py:190} INFO -       [end of output]
[2023-09-19T07:16:03.253+0000] {process_utils.py:190} INFO - 
[2023-09-19T07:16:03.253+0000] {process_utils.py:190} INFO -   note: This error originates from a subprocess, and is likely not a problem with pip.
[2023-09-19T07:16:03.253+0000] {process_utils.py:190} INFO - error: metadata-generation-failed
[2023-09-19T07:16:03.253+0000] {process_utils.py:190} INFO - 
[2023-09-19T07:16:03.254+0000] {process_utils.py:190} INFO - × Encountered error while generating package metadata.
[2023-09-19T07:16:03.254+0000] {process_utils.py:190} INFO - ╰─> See above for output.
[2023-09-19T07:16:03.254+0000] {process_utils.py:190} INFO - 
[2023-09-19T07:16:03.255+0000] {process_utils.py:190} INFO - note: This is an issue with the package mentioned above, not pip.
[2023-09-19T07:16:03.255+0000] {process_utils.py:190} INFO - hint: See above for details.
[2023-09-19T07:16:03.451+0000] {process_utils.py:190} INFO - 
[2023-09-19T07:16:03.451+0000] {process_utils.py:190} INFO - [notice] A new release of pip is available: 23.2 -> 23.2.1
[2023-09-19T07:16:03.452+0000] {process_utils.py:190} INFO - [notice] To update, run: python -m pip install --upgrade pip
[2023-09-19T07:16:03.516+0000] {taskinstance.py:1935} ERROR - Task failed with exception
Traceback (most recent call last):
  File "/home/airflow/.local/lib/python3.8/site-packages/airflow/operators/python.py", line 395, in execute
    return super().execute(context=serializable_context)
  File "/home/airflow/.local/lib/python3.8/site-packages/airflow/operators/python.py", line 192, in execute
    return_value = self.execute_callable()
  File "/home/airflow/.local/lib/python3.8/site-packages/airflow/operators/python.py", line 594, in execute_callable
    prepare_virtualenv(
  File "/home/airflow/.local/lib/python3.8/site-packages/airflow/utils/python_virtualenv.py", line 100, in prepare_virtualenv
    execute_in_subprocess(pip_cmd)
  File "/home/airflow/.local/lib/python3.8/site-packages/airflow/utils/process_utils.py", line 171, in execute_in_subprocess
    execute_in_subprocess_with_kwargs(cmd, cwd=cwd)
  File "/home/airflow/.local/lib/python3.8/site-packages/airflow/utils/process_utils.py", line 194, in execute_in_subprocess_with_kwargs
    raise subprocess.CalledProcessError(exit_code, cmd)
subprocess.CalledProcessError: Command '['/tmp/venvxla5nf0v/bin/pip', 'install', '-r', '/tmp/venvxla5nf0v/requirements.txt']' returned non-zero exit status 1.
[2023-09-19T07:16:03.524+0000] {taskinstance.py:1398} INFO - Marking task as FAILED. dag_id=weather_data, task_id=extract_data, execution_date=20230919T071559, start_date=20230919T071600, end_date=20230919T071603
[2023-09-19T07:16:03.533+0000] {standard_task_runner.py:104} ERROR - Failed to execute job 57 for task extract_data (Command '['/tmp/venvxla5nf0v/bin/pip', 'install', '-r', '/tmp/venvxla5nf0v/requirements.txt']' returned non-zero exit status 1.; 4687)
[2023-09-19T07:16:03.562+0000] {local_task_job_runner.py:228} INFO - Task exited with return code 1
[2023-09-19T07:16:03.576+0000] {taskinstance.py:2776} INFO - 0 downstream tasks scheduled from follow-on schedule check
