[2023-09-16T19:21:53.009+0000] {taskinstance.py:1103} INFO - Dependencies all met for dep_context=non-requeueable deps ti=<TaskInstance: weather_data.extract_data manual__2023-09-16T19:21:51.846892+00:00 [queued]>
[2023-09-16T19:21:53.015+0000] {taskinstance.py:1103} INFO - Dependencies all met for dep_context=requeueable deps ti=<TaskInstance: weather_data.extract_data manual__2023-09-16T19:21:51.846892+00:00 [queued]>
[2023-09-16T19:21:53.016+0000] {taskinstance.py:1308} INFO - Starting attempt 1 of 1
[2023-09-16T19:21:53.025+0000] {taskinstance.py:1327} INFO - Executing <Task(PythonOperator): extract_data> on 2023-09-16 19:21:51.846892+00:00
[2023-09-16T19:21:53.030+0000] {standard_task_runner.py:57} INFO - Started process 5027 to run task
[2023-09-16T19:21:53.034+0000] {standard_task_runner.py:84} INFO - Running: ['***', 'tasks', 'run', 'weather_data', 'extract_data', 'manual__2023-09-16T19:21:51.846892+00:00', '--job-id', '44', '--raw', '--subdir', 'DAGS_FOLDER/weather_dag.py', '--cfg-path', '/tmp/tmp4u8qpzuu']
[2023-09-16T19:21:53.035+0000] {standard_task_runner.py:85} INFO - Job 44: Subtask extract_data
[2023-09-16T19:21:53.077+0000] {task_command.py:410} INFO - Running <TaskInstance: weather_data.extract_data manual__2023-09-16T19:21:51.846892+00:00 [running]> on host 6e5c3b2e8b65
[2023-09-16T19:21:53.146+0000] {taskinstance.py:1547} INFO - Exporting env vars: AIRFLOW_CTX_DAG_OWNER='***' AIRFLOW_CTX_DAG_ID='weather_data' AIRFLOW_CTX_TASK_ID='extract_data' AIRFLOW_CTX_EXECUTION_DATE='2023-09-16T19:21:51.846892+00:00' AIRFLOW_CTX_TRY_NUMBER='1' AIRFLOW_CTX_DAG_RUN_ID='manual__2023-09-16T19:21:51.846892+00:00'
[2023-09-16T19:21:53.464+0000] {taskinstance.py:1824} ERROR - Task failed with exception
Traceback (most recent call last):
  File "/home/airflow/.local/lib/python3.7/site-packages/airflow/operators/python.py", line 181, in execute
    return_value = self.execute_callable()
  File "/home/airflow/.local/lib/python3.7/site-packages/airflow/operators/python.py", line 198, in execute_callable
    return self.python_callable(*self.op_args, **self.op_kwargs)
  File "/opt/airflow/dags/weather_dag.py", line 40, in download_data
    save_data(data, extraction_timestamp)
  File "/opt/airflow/dags/weather_dag.py", line 59, in save_data
    print(json.dumps(record), file=f)
  File "/usr/local/lib/python3.7/json/__init__.py", line 231, in dumps
    return _default_encoder.encode(obj)
  File "/usr/local/lib/python3.7/json/encoder.py", line 199, in encode
    chunks = self.iterencode(o, _one_shot=True)
  File "/usr/local/lib/python3.7/json/encoder.py", line 257, in iterencode
    return _iterencode(o, 0)
  File "/usr/local/lib/python3.7/json/encoder.py", line 179, in default
    raise TypeError(f'Object of type {o.__class__.__name__} '
TypeError: Object of type date is not JSON serializable
[2023-09-16T19:21:53.482+0000] {taskinstance.py:1350} INFO - Marking task as FAILED. dag_id=weather_data, task_id=extract_data, execution_date=20230916T192151, start_date=20230916T192153, end_date=20230916T192153
[2023-09-16T19:21:53.496+0000] {standard_task_runner.py:109} ERROR - Failed to execute job 44 for task extract_data (Object of type date is not JSON serializable; 5027)
[2023-09-16T19:21:53.535+0000] {local_task_job_runner.py:225} INFO - Task exited with return code 1
[2023-09-16T19:21:53.552+0000] {taskinstance.py:2653} INFO - 0 downstream tasks scheduled from follow-on schedule check
